Workbook

Sheet README
A1: Position Price Verification - Valuation Control Workbook
A2: SYNTHETIC DATA ONLY. No real bank, client or market data is used. Built as a learning / portfolio project.
A4: Purpose
A5: Compare desk marks (BookPrice) with independent prices, flag positions outside asset-class tolerance, and report data-quality issues.
A7: Sheets
A8: Thresholds - tolerance per asset class and the Report Date (inputs, blue font).
A9: Raw_Data - deliberately messy input: duplicates, missing independent prices, stale dates, text-case/space issues, one unmapped asset class label.
A10: Checks - formula-driven control test on every Raw_Data row (works without macros).
A11: Summary - breach counts, rates and net market-value differences by asset class and by desk, plus data-quality counts.
A12: VBA (separate file ValuationAutomation.bas) - one-click automation: cleans, tests, builds Clean_Data + Exceptions + Run_Log, exports Clean_Positions.csv.
A14: Rules
A15: Variance % = (BookPrice - IndependentPrice) / IndependentPrice.
... A26: Blue font = hard-coded input | Black = formula | Green = link to another sheet | Yellow fill = key input to change.

Sheet Thresholds
A1: Asset Class | B1: Tolerance (%) | D1: Report Date | E1: 46293
A2: Equity | B2: 0.01
A3: Corporate Bond | B3: 0.005
A4: Government Bond | B4: 0.0025
A5: FX Forward | B5: 0.003
A7: Note: tolerances are illustrative author assumptions. Edit blue cells to test other thresholds; Checks and Summary recalculate.

Sheet Raw_Data
A1: PositionID | B1: ValuationDate | C1: Desk | D1: AssetClass | E1: Instrument | F1: Currency | G1: Quantity | H1: BookPrice | I1: IndependentPrice
A2: P0001 | B2: 46293 | C2: Singapore Equities | D2: Equity | E2: EQ-0053 | F2: SGD | G2: 36166 | H2: 149.54 | I2: 149.33
A3: P0002 | B3: 46293 | C3: Singapore FX | D3: FX Forward | E3: FX-0004 | F3: SGD | G3: 4061266 | H3: 1.43472 | I3: 1.43723
A4: P0003 | B4: 46293 | C4: New York Credit | D4: Corporate Bond | E4: CB-0042 | F4: USD | G4: 15502 | H4: 107.201 | I4: 107.128
A5: P0004 | B5: 46293 | C5: London Credit | D5: Corporate Bond | E5: CB-0003 | F5: GBP | G5: 1316 | H5: 103.86 | I5: 104.121
A6: P0005 | B6: 46293 | C6: Zurich FX | D6: FX Forward | E6: FX-0026 | F6: CHF | G6: 4847348 | H6: 1.13117 | I6: 1.12959
A7: P0006 | B7: 46293 | C7: Singapore FX | D7: FX Forward | E7: FX-0038 | F7: SGD | G7: 1694942 | H7: 0.819 | I7: 0.82022
A8: P0007 | B8: 46293 | C8: Zurich Equities | D8: Equity | E8: EQ-0050 | F8: CHF | G8: 47824 | H8: 36.97 | I8: 37.02
A9: P0008 | B9: 46293 | C9: New York Credit | D9: Corporate Bond | E9: CB-0017 | F9: USD | G9: 1904 | H9: 102.872 | I9: 102.744
A10: P0009 | B10: 46293 | C10: London Credit | D10: Corporate Bond | E10: CB-0065 | F10: GBP | G10: 4748 | H10: 101.941 | I10: 101.92
A11: P0010 | B11: 46293 | C11: Zurich Equities | D11: Equity | E11: EQ-0048 | F11: CHF | G11: 23319 | H11: 204.52 | I11: 204.34
A12: P0011 | B12: 46293 | C12: Singapore FX | D12: FX Forward | E12: FX-0016 | F12: SGD | G12: 1309263 | H12: 0.61535 | I12: 0.61606
A13: P0012 | B13: 46293 | C13: New York Credit | D13: Corporate Bond | E13: CB-0030 | F13: USD | G13: 15488 | H13: 99.44 | I13: 99.439
... A28: P0026 | B28: 46293 | C28: New York Rates | D28: Government Bond | E28: GB-0011 | F28: USD | G28: 16976 | H28: 98.691 | I28: 98.779
A29: P0027 | B29: 46293 | C29: London Credit | D29: Corporate Bond | E29: CB-0048 | F29: GBP | G29: 6007 | H29: 95.7
A30: P0028 | B30: 46293 | C30: New York Rates | D30: Gov Bond | E30: GB-0035 | F30: USD | G30: 15051 | H30: 103.268 | I30: 103.308
A31: P0029 | B31: 46293 | C31: New York Credit | D31: Corporate Bond | E31: CB-0036 | F31: USD | G31: 19863 | H31: 106.178 | I31: 106.471
A32: P0030 | B32: 46293 | C32: Singapore Equities | D32: equity | E32: EQ-0011 | F32: SGD | G32: 15035 | H32: 181.66 | I32: 181.74
A33: P0031 | B33: 46293 | C33: London Rates | D33: Government Bond | E33: GB-0010 | F33: GBP | G33: 19672 | H33: 102.004 | I33: 102.042
A34: P0032 | B34: 46293 | C34: London Credit | D34: Corporate Bond | E34: CB-0002 | F34: GBP | G34: 9583 | H34: 102.194 | I34: 102.261
A35: P0033 | B35: 46293 | C35: Singapore Equities | D35: Equity | E35: EQ-0074 | F35: SGD | G35: 46207 | H35: 253.45 | I35: 254.29
A36: P0034 | B36: 46293 | C36: New York Rates | D36: Government Bond | E36: GB-0027 | F36: USD | G36: 17085 | H36: 101.579 | I36: 101.436
A37: P0035 | B37: 46293 | C37: Singapore Equities | D37: Equity | E37: EQ-0075 | F37: SGD | G37: 612 | H37: 191.27 | I37: 189.89
A38: P0036 | B38: 46293 | C38: New York Credit | D38: Corporate Bond | E38: CB-0026 | F38: USD | G38: 11688 | H38: 102.67 | I38: 102.283
A39: P0037 | B39: 46293 | C39: Zurich FX | D39: FX Forward | E39: FX-0040 | F39: CHF | G39: 430700 | H39: 1.5034 | I39: 1.50666
A40: P0038 | B40: 46293 | C40: Singapore Equities | D40: Equity | E40: EQ-0063 | F40: SGD | G40: 33381 | H40: 160.8 | I40: 160.52
A41: P0039 | B41: 46293 | C41: New York Credit | D41: Corporate Bond | E41: CB-0029 | F41: USD | G41: 15086 | H41: 100.767 | I41: 100.56
... A81: P0079 | B81: 46293 | C81: Zurich FX | D81: FX Forward | E81: FX-0001 | F81: CHF | G81: 1984925 | H81: 0.91075 | I81: 0.90936
A82: P0080 | B82: 46293 | C82: New York Credit | D82: Corporate Bond | E82: CB-0062 | F82: USD | G82: 18675 | H82: 92.31
A83: P0081 | B83: 46293 | C83: Zurich FX | D83: FX Forward | E83: FX-0005 | F83: CHF | G83: 4363433 | H83: 1.05679 | I83: 1.05616
A84: P0082 | B84: 46293 | C84: London Credit | D84: Corporate Bond | E84: CB-0038 | F84: GBP | G84: 4492 | H84: 106.283 | I84: 106.105
A85: P0083 | B85: 46293 | C85: Singapore FX | D85: FX Forward | E85: FX-0013 | F85: SGD | G85: 1375951 | H85: 0.98608 | I85: 0.9875
A86: P0084 | B86: 46293 | C86: Zurich Equities | D86: Equity | E86: EQ-0054 | F86: CHF | G86: 35527 | H86: 34.16 | I86: 34.21
A87: P0085 | B87: 46293 | C87: London Rates | D87: Government Bond | E87: GB-0006 | F87: GBP | G87: 18096 | H87: 99.484 | I87: 99.518
A88: P0086 | B88: 46293 | C88: New York Rates | D88: Government Bond | E88: GB-0033 | F88: USD | G88: 14637 | H88: 96.681 | I88: 96.68
A89: P0087 | B89: 46293 | C89: Singapore FX | D89: FX Forward | E89: FX-0024 | F89: SGD | G89: 485800 | H89: 1.50342 | I89: 1.50442
A90: P0088 | B90: 46293 | C90: London Credit | D90: Corporate Bond | E90: CB-0019 | F90: GBP | G90: 15239 | H90: 101.289 | I90: 101.219
A91: P0089 | B91: 46293 | C91: Zurich Equities | D91: Equity | E91: EQ-0003 | F91: CHF | G91: 15347 | H91: 185.34 | I91: 184.94
A92: P0090 | B92: 46293 | C92: Zurich Equities | D92: EQUITY | E92: EQ-0042 | F92: CHF | G92: 38655 | H92: 114.66 | I92: 114.69
A93: P0091 | B93: 46293 | C93: London Credit | D93: Corporate Bond | E93: CB-0035 | F93: GBP | G93: 15923 | H93: 107.743 | I93: 106.166
...

Sheet Checks
A1: PositionID | B1: Desk | C1: Asset Class (clean) | D1: Quantity | E1: Book Price | F1: Independent Price | G1: Variance % | H1: Tolerance % | I1: MV Diff (local ccy) | J1: Status | K1: Duplicate? | L1: Valuation Date Flag
A2: =Raw_Data!A2 -> P0001 | B2: =Raw_Data!C2 -> Singapore Equities | C2: =IFERROR(INDEX(Thresholds!$A$2:$A$5,MATCH(TRIM(Raw_Data!D2),Thresholds!$A$2:$A$5,0)),"UNMAPPED") -> Equity | D2: =Raw_Data!G2 -> 36166 | E2: =Raw_Data!H2 -> 149.54 | F2: =IF(Raw_Data!I2="","",Raw_Data!I2) -> 149.33 | G2: =IF(F2="","",(E2-F2)/F2) -> 0.0014062814 | H2: =IFERROR(INDEX(Thresholds!$B$2:$B$5,MATCH(C2,Thresholds!$A$2:$A$5,0)),"") -> 0.01 | I2: =IF(F2="","",D2*(E2-F2)) -> 7594.86 | J2: =IF(C2="UNMAPPED","UNMAPPED ASSET CLASS",IF(F2="","NO INDEPENDENT PRICE",IF(ABS(G2)>H2,"BREACH","OK"))) -> OK | K2: =IF(COUNTIF(Raw_Data!$A$2:A2,Raw_Data!A2)>1,"DUP","UNIQUE") -> UNIQUE | L2: =IF(Raw_Data!B2<>Thresholds!$E$1,"STALE","CURRENT") -> CURRENT
A3: =Raw_Data!A3 -> P0002 | B3: =Raw_Data!C3 -> Singapore FX | C3: =IFERROR(INDEX(Thresholds!$A$2:$A$5,MATCH(TRIM(Raw_Data!D3),Thresholds!$A$2:$A$5,0)),"UNMAPPED") -> FX Forward | D3: =Raw_Data!G3 -> 4061266 | E3: =Raw_Data!H3 -> 1.43472 | F3: =IF(Raw_Data!I3="","",Raw_Data!I3) -> 1.43723 | G3: =IF(F3="","",(E3-F3)/F3) -> -0.001746415 | H3: =IFERROR(INDEX(Thresholds!$B$2:$B$5,MATCH(C3,Thresholds!$A$2:$A$5,0)),"") -> 0.003 | I3: =IF(F3="","",D3*(E3-F3)) -> -10193.778 | J3: =IF(C3="UNMAPPED","UNMAPPED ASSET CLASS",IF(F3="","NO INDEPENDENT PRICE",IF(ABS(G3)>H3,"BREACH","OK"))) -> OK | K3: =IF(COUNTIF(Raw_Data!$A$2:A3,Raw_Data!A3)>1,"DUP","UNIQUE") -> UNIQUE | L3: =IF(Raw_Data!B3<>Thresholds!$E$1,"STALE","CURRENT") -> CURRENT
A4: =Raw_Data!A4 -> P0003 | B4: =Raw_Data!C4 -> New York Credit | C4: =IFERROR(INDEX(Thresholds!$A$2:$A$5,MATCH(TRIM(Raw_Data!D4),Thresholds!$A$2:$A$5,0)),"UNMAPPED") -> Corporate Bond | D4: =Raw_Data!G4 -> 15502 | E4: =Raw_Data!H4 -> 107.201 | F4: =IF(Raw_Data!I4="","",Raw_Data!I4) -> 107.128 | G4: =IF(F4="","",(E4-F4)/F4) -> 0.00068142782 | H4: =IFERROR(INDEX(Thresholds!$B$2:$B$5,MATCH(C4,Thresholds!$A$2:$A$5,0)),"") -> 0.005 | I4: =IF(F4="","",D4*(E4-F4)) -> 1131.646 | J4: =IF(C4="UNMAPPED","UNMAPPED ASSET CLASS",IF(F4="","NO INDEPENDENT PRICE",IF(ABS(G4)>H4,"BREACH","OK"))) -> OK | K4: =IF(COUNTIF(Raw_Data!$A$2:A4,Raw_Data!A4)>1,"DUP","UNIQUE") -> UNIQUE | L4: =IF(Raw_Data!B4<>Thresholds!$E$1,"STALE","CURRENT") -> CURRENT
A5: =Raw_Data!A5 -> P0004 | B5: =Raw_Data!C5 -> London Credit | C5: =IFERROR(INDEX(Thresholds!$A$2:$A$5,MATCH(TRIM(Raw_Data!D5),Thresholds!$A$2:$A$5,0)),"UNMAPPED") -> Corporate Bond | D5: =Raw_Data!G5 -> 1316 | E5: =Raw_Data!H5 -> 103.86 | F5: =IF(Raw_Data!I5="","",Raw_Data!I5) -> 104.121 | G5: =IF(F5="","",(E5-F5)/F5) -> -0.0025066989 | H5: =IFERROR(INDEX(Thresholds!$B$2:$B$5,MATCH(C5,Thresholds!$A$2:$A$5,0)),"") -> 0.005 | I5: =IF(F5="","",D5*(E5-F5)) -> -343.476 | J5: =IF(C5="UNMAPPED","UNMAPPED ASSET CLASS",IF(F5="","NO INDEPENDENT PRICE",IF(ABS(G5)>H5,"BREACH","OK"))) -> OK | K5: =IF(COUNTIF(Raw_Data!$A$2:A5,Raw_Data!A5)>1,"DUP","UNIQUE") -> UNIQUE | L5: =IF(Raw_Data!B5<>Thresholds!$E$1,"STALE","CURRENT") -> CURRENT
A6: =Raw_Data!A6 -> P0005 | B6: =Raw_Data!C6 -> Zurich FX | C6: =IFERROR(INDEX(Thresholds!$A$2:$A$5,MATCH(TRIM(Raw_Data!D6),Thresholds!$A$2:$A$5,0)),"UNMAPPED") -> FX Forward | D6: =Raw_Data!G6 -> 4847348 | E6: =Raw_Data!H6 -> 1.13117 | F6: =IF(Raw_Data!I6="","",Raw_Data!I6) -> 1.12959 | G6: =IF(F6="","",(E6-F6)/F6) -> 0.0013987376 | H6: =IFERROR(INDEX(Thresholds!$B$2:$B$5,MATCH(C6,Thresholds!$A$2:$A$5,0)),"") -> 0.003 | I6: =IF(F6="","",D6*(E6-F6)) -> 7658.8098 | J6: =IF(C6="UNMAPPED","UNMAPPED ASSET CLASS",IF(F6="","NO INDEPENDENT PRICE",IF(ABS(G6)>H6,"BREACH","OK"))) -> OK | K6: =IF(COUNTIF(Raw_Data!$A$2:A6,Raw_Data!A6)>1,"DUP","UNIQUE") -> UNIQUE | L6: =IF(Raw_Data!B6<>Thresholds!$E$1,"STALE","CURRENT") -> CURRENT
A7: =Raw_Data!A7 -> P0006 | B7: =Raw_Data!C7 -> Singapore FX | C7: =IFERROR(INDEX(Thresholds!$A$2:$A$5,MATCH(TRIM(Raw_Data!D7),Thresholds!$A$2:$A$5,0)),"UNMAPPED") -> FX Forward | D7: =Raw_Data!G7 -> 1694942 | E7: =Raw_Data!H7 -> 0.819 | F7: =IF(Raw_Data!I7="","",Raw_Data!I7) -> 0.82022 | G7: =IF(F7="","",(E7-F7)/F7) -> -0.0014874058 | H7: =IFERROR(INDEX(Thresholds!$B$2:$B$5,MATCH(C7,Thresholds!$A$2:$A$5,0)),"") -> 0.003 | I7: =IF(F7="","",D7*(E7-F7)) -> -2067.8292 | J7: =IF(C7="UNMAPPED","UNMAPPED ASSET CLASS",IF(F7="","NO INDEPENDENT PRICE",IF(ABS(G7)>H7,"BREACH","OK"))) -> OK | K7: =IF(COUNTIF(Raw_Data!$A$2:A7,Raw_Data!A7)>1,"DUP","UNIQUE") -> UNIQUE | L7: =IF(Raw_Data!B7<>Thresholds!$E$1,"STALE","CURRENT") -> CURRENT
A8: =Raw_Data!A8 -> P0007 | B8: =Raw_Data!C8 -> Zurich Equities | C8: =IFERROR(INDEX(Thresholds!$A$2:$A$5,MATCH(TRIM(Raw_Data!D8),Thresholds!$A$2:$A$5,0)),"UNMAPPED") -> Equity | D8: =Raw_Data!G8 -> 47824 | E8: =Raw_Data!H8 -> 36.97 | F8: =IF(Raw_Data!I8="","",Raw_Data!I8) -> 37.02 | G8: =IF(F8="","",(E8-F8)/F8) -> -0.0013506213 | H8: =IFERROR(INDEX(Thresholds!$B$2:$B$5,MATCH(C8,Thresholds!$A$2:$A$5,0)),"") -> 0.01 | I8: =IF(F8="","",D8*(E8-F8)) -> -2391.2 | J8: =IF(C8="UNMAPPED","UNMAPPED ASSET CLASS",IF(F8="","NO INDEPENDENT PRICE",IF(ABS(G8)>H8,"BREACH","OK"))) -> OK | K8: =IF(COUNTIF(Raw_Data!$A$2:A8,Raw_Data!A8)>1,"DUP","UNIQUE") -> UNIQUE | L8: =IF(Raw_Data!B8<>Thresholds!$E$1,"STALE","CURRENT") -> CURRENT
A9: =Raw_Data!A9 -> P0008 | B9: =Raw_Data!C9 -> New York Credit | C9: =IFERROR(INDEX(Thresholds!$A$2:$A$5,MATCH(TRIM(Raw_Data!D9),Thresholds!$A$2:$A$5,0)),"UNMAPPED") -> Corporate Bond | D9: =Raw_Data!G9 -> 1904 | E9: =Raw_Data!H9 -> 102.872 | F9: =IF(Raw_Data!I9="","",Raw_Data!I9) -> 102.744 | G9: =IF(F9="","",(E9-F9)/F9) -> 0.0012458148 | H9: =IFERROR(INDEX(Thresholds!$B$2:$B$5,MATCH(C9,Thresholds!$A$2:$A$5,0)),"") -> 0.005 | I9: =IF(F9="","",D9*(E9-F9)) -> 243.712 | J9: =IF(C9="UNMAPPED","UNMAPPED ASSET CLASS",IF(F9="","NO INDEPENDENT PRICE",IF(ABS(G9)>H9,"BREACH","OK"))) -> OK | K9: =IF(COUNTIF(Raw_Data!$A$2:A9,Raw_Data!A9)>1,"DUP","UNIQUE") -> UNIQUE | L9: =IF(Raw_Data!B9<>Thresholds!$E$1,"STALE","CURRENT") -> CURRENT
A10: =Raw_Data!A10 -> P0009 | B10: =Raw_Data!C10 -> London Credit | C10: =IFERROR(INDEX(Thresholds!$A$2:$A$5,MATCH(TRIM(Raw_Data!D10),Thresholds!$A$2:$A$5,0)),"UNMAPPED") -> Corporate Bond | D10: =Raw_Data!G10 -> 4748 | E10: =Raw_Data!H10 -> 101.941 | F10: =IF(Raw_Data!I10="","",Raw_Data!I10) -> 101.92 | G10: =IF(F10="","",(E10-F10)/F10) -> 0.00020604396 | H10: =IFERROR(INDEX(Thresholds!$B$2:$B$5,MATCH(C10,Thresholds!$A$2:$A$5,0)),"") -> 0.005 | I10: =IF(F10="","",D10*(E10-F10)) -> 99.708 | J10: =IF(C10="UNMAPPED","UNMAPPED ASSET CLASS",IF(F10="","NO INDEPENDENT PRICE",IF(ABS(G10)>H10,"BREACH","OK"))) -> OK | K10: =IF(COUNTIF(Raw_Data!$A$2:A10,Raw_Data!A10)>1,"DUP","UNIQUE") -> UNIQUE | L10: =IF(Raw_Data!B10<>Thresholds!$E$1,"STALE","CURRENT") -> CURRENT
A11: =Raw_Data!A11 -> P0010 | B11: =Raw_Data!C11 -> Zurich Equities | C11: =IFERROR(INDEX(Thresholds!$A$2:$A$5,MATCH(TRIM(Raw_Data!D11),Thresholds!$A$2:$A$5,0)),"UNMAPPED") -> Equity | D11: =Raw_Data!G11 -> 23319 | E11: =Raw_Data!H11 -> 204.52 | F11: =IF(Raw_Data!I11="","",Raw_Data!I11) -> 204.34 | G11: =IF(F11="","",(E11-F11)/F11) -> 0.0008808848 | H11: =IFERROR(INDEX(Thresholds!$B$2:$B$5,MATCH(C11,Thresholds!$A$2:$A$5,0)),"") -> 0.01 | I11: =IF(F11="","",D11*(E11-F11)) -> 4197.42 | J11: =IF(C11="UNMAPPED","UNMAPPED ASSET CLASS",IF(F11="","NO INDEPENDENT PRICE",IF(ABS(G11)>H11,"BREACH","OK"))) -> OK | K11: =IF(COUNTIF(Raw_Data!$A$2:A11,Raw_Data!A11)>1,"DUP","UNIQUE") -> UNIQUE | L11: =IF(Raw_Data!B11<>Thresholds!$E$1,"STALE","CURRENT") -> CURRENT
A12: =Raw_Data!A12 -> P0011 | B12: =Raw_Data!C12 -> Singapore FX | C12: =IFERROR(INDEX(Thresholds!$A$2:$A$5,MATCH(TRIM(Raw_Data!D12),Thresholds!$A$2:$A$5,0)),"UNMAPPED") -> FX Forward | D12: =Raw_Data!G12 -> 1309263 | E12: =Raw_Data!H12 -> 0.61535 | F12: =IF(Raw_Data!I12="","",Raw_Data!I12) -> 0.61606 | G12: =IF(F12="","",(E12-F12)/F12) -> -0.0011524851 | H12: =IFERROR(INDEX(Thresholds!$B$2:$B$5,MATCH(C12,Thresholds!$A$2:$A$5,0)),"") -> 0.003 | I12: =IF(F12="","",D12*(E12-F12)) -> -929.57673 | J12: =IF(C12="UNMAPPED","UNMAPPED ASSET CLASS",IF(F12="","NO INDEPENDENT PRICE",IF(ABS(G12)>H12,"BREACH","OK"))) -> OK | K12: =IF(COUNTIF(Raw_Data!$A$2:A12,Raw_Data!A12)>1,"DUP","UNIQUE") -> UNIQUE | L12: =IF(Raw_Data!B12<>Thresholds!$E$1,"STALE","CURRENT") -> CURRENT
A13: =Raw_Data!A13 -> P0012 | B13: =Raw_Data!C13 -> New York Credit | C13: =IFERROR(INDEX(Thresholds!$A$2:$A$5,MATCH(TRIM(Raw_Data!D13),Thresholds!$A$2:$A$5,0)),"UNMAPPED") -> Corporate Bond | D13: =Raw_Data!G13 -> 15488 | E13: =Raw_Data!H13 -> 99.44 | F13: =IF(Raw_Data!I13="","",Raw_Data!I13) -> 99.439 | G13: =IF(F13="","",(E13-F13)/F13) -> 1.0056416e-05 | H13: =IFERROR(INDEX(Thresholds!$B$2:$B$5,MATCH(C13,Thresholds!$A$2:$A$5,0)),"") -> 0.005 | I13: =IF(F13="","",D13*(E13-F13)) -> 15.488 | J13: =IF(C13="UNMAPPED","UNMAPPED ASSET CLASS",IF(F13="","NO INDEPENDENT PRICE",IF(ABS(G13)>H13,"BREACH","OK"))) -> OK | K13: =IF(COUNTIF(Raw_Data!$A$2:A13,Raw_Data!A13)>1,"DUP","UNIQUE") -> UNIQUE | L13: =IF(Raw_Data!B13<>Thresholds!$E$1,"STALE","CURRENT") -> CURRENT
... A255: =Raw_Data!A255 -> P0241 | B255: =Raw_Data!C255 -> Zurich FX | C255: =IFERROR(INDEX(Thresholds!$A$2:$A$5,MATCH(TRIM(Raw_Data!D255),Thresholds!$A$2:$A$5,0)),"UNMAPPED") -> FX Forward | D255: =Raw_Data!G255 -> 1495568 | E255: =Raw_Data!H255 -> 1.36037 | F255: =IF(Raw_Data!I255="","",Raw_Data!I255) -> 1.3483 | G255: =IF(F255="","",(E255-F255)/F255) -> 0.0089520136 | H255: =IFERROR(INDEX(Thresholds!$B$2:$B$5,MATCH(C255,Thresholds!$A$2:$A$5,0)),"") -> 0.003 | I255: =IF(F255="","",D255*(E255-F255)) -> 18051.506 | J255: =IF(C255="UNMAPPED","UNMAPPED ASSET CLASS",IF(F255="","NO INDEPENDENT PRICE",IF(ABS(G255)>H255,"BREACH","OK"))) -> BREACH | K255: =IF(COUNTIF(Raw_Data!$A$2:A255,Raw_Data!A255)>1,"DUP","UNIQUE") -> DUP | L255: =IF(Raw_Data!B255<>Thresholds!$E$1,"STALE","CURRENT") -> CURRENT

Sheet Summary
A1: Valuation Control Summary
A2: Report Date | B2: =Thresholds!E1 -> 46293
A4: Results by Asset Class
A5: Asset Class | B5: Positions Tested | C5: OK | D5: Breaches | E5: No Indep. Price | F5: Breach Rate | G5: Net MV Diff (all tested) | H5: Net MV Diff (breaches)
A6: =Thresholds!A2 -> Equity | B6: =COUNTIFS(Checks!$C$2:$C$255,$A6,Checks!$K$2:$K$255,"UNIQUE",Checks!$J$2:$J$255,"OK")+COUNTIFS(Checks!$C$2:$C$255,$A6,Checks!$K$2:$K$255,"UNIQUE",Checks!$J$2:$J$255,"BREACH") -> 78 | C6: =COUNTIFS(Checks!$C$2:$C$255,$A6,Checks!$K$2:$K$255,"UNIQUE",Checks!$J$2:$J$255,"OK") -> 67 | D6: =COUNTIFS(Checks!$C$2:$C$255,$A6,Checks!$K$2:$K$255,"UNIQUE",Checks!$J$2:$J$255,"BREACH") -> 11 | E6: =COUNTIFS(Checks!$C$2:$C$255,$A6,Checks!$K$2:$K$255,"UNIQUE",Checks!$J$2:$J$255,"NO INDEPENDENT PRICE") -> 2 | F6: =IF((C6+D6)=0,0,D6/(C6+D6)) -> 0.14102564 | G6: =SUMIFS(Checks!$I$2:$I$255,Checks!$C$2:$C$255,$A6,Checks!$K$2:$K$255,"UNIQUE",Checks!$J$2:$J$255,"<>UNMAPPED ASSET CLASS") -> -253878.63 | H6: =SUMIFS(Checks!$I$2:$I$255,Checks!$C$2:$C$255,$A6,Checks!$K$2:$K$255,"UNIQUE",Checks!$J$2:$J$255,"BREACH") -> 69544.16
A7: =Thresholds!A3 -> Corporate Bond | B7: =COUNTIFS(Checks!$C$2:$C$255,$A7,Checks!$K$2:$K$255,"UNIQUE",Checks!$J$2:$J$255,"OK")+COUNTIFS(Checks!$C$2:$C$255,$A7,Checks!$K$2:$K$255,"UNIQUE",Checks!$J$2:$J$255,"BREACH") -> 68 | C7: =COUNTIFS(Checks!$C$2:$C$255,$A7,Checks!$K$2:$K$255,"UNIQUE",Checks!$J$2:$J$255,"OK") -> 64 | D7: =COUNTIFS(Checks!$C$2:$C$255,$A7,Checks!$K$2:$K$255,"UNIQUE",Checks!$J$2:$J$255,"BREACH") -> 4 | E7: =COUNTIFS(Checks!$C$2:$C$255,$A7,Checks!$K$2:$K$255,"UNIQUE",Checks!$J$2:$J$255,"NO INDEPENDENT PRICE") -> 2 | F7: =IF((C7+D7)=0,0,D7/(C7+D7)) -> 0.058823529 | G7: =SUMIFS(Checks!$I$2:$I$255,Checks!$C$2:$C$255,$A7,Checks!$K$2:$K$255,"UNIQUE",Checks!$J$2:$J$255,"<>UNMAPPED ASSET CLASS") -> -36124.328 | H7: =SUMIFS(Checks!$I$2:$I$255,Checks!$C$2:$C$255,$A7,Checks!$K$2:$K$255,"UNIQUE",Checks!$J$2:$J$255,"BREACH") -> -3355.556
A8: =Thresholds!A4 -> Government Bond | B8: =COUNTIFS(Checks!$C$2:$C$255,$A8,Checks!$K$2:$K$255,"UNIQUE",Checks!$J$2:$J$255,"OK")+COUNTIFS(Checks!$C$2:$C$255,$A8,Checks!$K$2:$K$255,"UNIQUE",Checks!$J$2:$J$255,"BREACH") -> 56 | C8: =COUNTIFS(Checks!$C$2:$C$255,$A8,Checks!$K$2:$K$255,"UNIQUE",Checks!$J$2:$J$255,"OK") -> 53 | D8: =COUNTIFS(Checks!$C$2:$C$255,$A8,Checks!$K$2:$K$255,"UNIQUE",Checks!$J$2:$J$255,"BREACH") -> 3 | E8: =COUNTIFS(Checks!$C$2:$C$255,$A8,Checks!$K$2:$K$255,"UNIQUE",Checks!$J$2:$J$255,"NO INDEPENDENT PRICE") -> 2 | F8: =IF((C8+D8)=0,0,D8/(C8+D8)) -> 0.053571429 | G8: =SUMIFS(Checks!$I$2:$I$255,Checks!$C$2:$C$255,$A8,Checks!$K$2:$K$255,"UNIQUE",Checks!$J$2:$J$255,"<>UNMAPPED ASSET CLASS") -> 6558.117 | H8: =SUMIFS(Checks!$I$2:$I$255,Checks!$C$2:$C$255,$A8,Checks!$K$2:$K$255,"UNIQUE",Checks!$J$2:$J$255,"BREACH") -> 6784.83
A9: =Thresholds!A5 -> FX Forward | B9: =COUNTIFS(Checks!$C$2:$C$255,$A9,Checks!$K$2:$K$255,"UNIQUE",Checks!$J$2:$J$255,"OK")+COUNTIFS(Checks!$C$2:$C$255,$A9,Checks!$K$2:$K$255,"UNIQUE",Checks!$J$2:$J$255,"BREACH") -> 40 | C9: =COUNTIFS(Checks!$C$2:$C$255,$A9,Checks!$K$2:$K$255,"UNIQUE",Checks!$J$2:$J$255,"OK") -> 36 | D9: =COUNTIFS(Checks!$C$2:$C$255,$A9,Checks!$K$2:$K$255,"UNIQUE",Checks!$J$2:$J$255,"BREACH") -> 4 | E9: =COUNTIFS(Checks!$C$2:$C$255,$A9,Checks!$K$2:$K$255,"UNIQUE",Checks!$J$2:$J$255,"NO INDEPENDENT PRICE") -> 0 | F9: =IF((C9+D9)=0,0,D9/(C9+D9)) -> 0.1 | G9: =SUMIFS(Checks!$I$2:$I$255,Checks!$C$2:$C$255,$A9,Checks!$K$2:$K$255,"UNIQUE",Checks!$J$2:$J$255,"<>UNMAPPED ASSET CLASS") -> 49762.478 | H9: =SUMIFS(Checks!$I$2:$I$255,Checks!$C$2:$C$255,$A9,Checks!$K$2:$K$255,"UNIQUE",Checks!$J$2:$J$255,"BREACH") -> 35039.193
A10: Total | B10: =SUM(B6:B9) -> 242 | C10: =SUM(C6:C9) -> 220 | D10: =SUM(D6:D9) -> 22 | E10: =SUM(E6:E9) -> 6 | F10: =IF((C10+D10)=0,0,D10/(C10+D10)) -> 0.090909091 | G10: =SUM(G6:G9) -> -233682.36 | H10: =SUM(H6:H9) -> 108012.63
A13: Results by Desk
A14: Desk | B14: Positions Tested | C14: OK | D14: Breaches | E14: No Indep. Price | F14: Breach Rate | G14: Net MV Diff (all tested) | H14: Net MV Diff (breaches)
A15: London Credit | B15: =COUNTIFS(Checks!$B$2:$B$255,$A15,Checks!$K$2:$K$255,"UNIQUE",Checks!$J$2:$J$255,"OK")+COUNTIFS(Checks!$B$2:$B$255,$A15,Checks!$K$2:$K$255,"UNIQUE",Checks!$J$2:$J$255,"BREACH") -> 36 | C15: =COUNTIFS(Checks!$B$2:$B$255,$A15,Checks!$K$2:$K$255,"UNIQUE",Checks!$J$2:$J$255,"OK") -> 34 | D15: =COUNTIFS(Checks!$B$2:$B$255,$A15,Checks!$K$2:$K$255,"UNIQUE",Checks!$J$2:$J$255,"BREACH") -> 2 | E15: =COUNTIFS(Checks!$B$2:$B$255,$A15,Checks!$K$2:$K$255,"UNIQUE",Checks!$J$2:$J$255,"NO INDEPENDENT PRICE") -> 1 | F15: =IF((C15+D15)=0,0,D15/(C15+D15)) -> 0.055555556 | G15: =SUMIFS(Checks!$I$2:$I$255,Checks!$B$2:$B$255,$A15,Checks!$K$2:$K$255,"UNIQUE",Checks!$J$2:$J$255,"<>UNMAPPED ASSET CLASS") -> 6555.952 | H15: =SUMIFS(Checks!$I$2:$I$255,Checks!$B$2:$B$255,$A15,Checks!$K$2:$K$255,"UNIQUE",Checks!$J$2:$J$255,"BREACH") -> 18004.652
A16: London Rates | B16: =COUNTIFS(Checks!$B$2:$B$255,$A16,Checks!$K$2:$K$255,"UNIQUE",Checks!$J$2:$J$255,"OK")+COUNTIFS(Checks!$B$2:$B$255,$A16,Checks!$K$2:$K$255,"UNIQUE",Checks!$J$2:$J$255,"BREACH") -> 24 | C16: =COUNTIFS(Checks!$B$2:$B$255,$A16,Checks!$K$2:$K$255,"UNIQUE",Checks!$J$2:$J$255,"OK") -> 23 | D16: =COUNTIFS(Checks!$B$2:$B$255,$A16,Checks!$K$2:$K$255,"UNIQUE",Checks!$J$2:$J$255,"BREACH") -> 1 | E16: =COUNTIFS(Checks!$B$2:$B$255,$A16,Checks!$K$2:$K$255,"UNIQUE",Checks!$J$2:$J$255,"NO INDEPENDENT PRICE") -> 2 | F16: =IF((C16+D16)=0,0,D16/(C16+D16)) -> 0.041666667 | G16: =SUMIFS(Checks!$I$2:$I$255,Checks!$B$2:$B$255,$A16,Checks!$K$2:$K$255,"UNIQUE",Checks!$J$2:$J$255,"<>UNMAPPED ASSET CLASS") -> 3654.621 | H16: =SUMIFS(Checks!$I$2:$I$255,Checks!$B$2:$B$255,$A16,Checks!$K$2:$K$255,"UNIQUE",Checks!$J$2:$J$255,"BREACH") -> 9215.982
A17: New York Credit | B17: =COUNTIFS(Checks!$B$2:$B$255,$A17,Checks!$K$2:$K$255,"UNIQUE",Checks!$J$2:$J$255,"OK")+COUNTIFS(Checks!$B$2:$B$255,$A17,Checks!$K$2:$K$255,"UNIQUE",Checks!$J$2:$J$255,"BREACH") -> 32 | C17: =COUNTIFS(Checks!$B$2:$B$255,$A17,Checks!$K$2:$K$255,"UNIQUE",Checks!$J$2:$J$255,"OK") -> 30 | D17: =COUNTIFS(Checks!$B$2:$B$255,$A17,Checks!$K$2:$K$255,"UNIQUE",Checks!$J$2:$J$255,"BREACH") -> 2 | E17: =COUNTIFS(Checks!$B$2:$B$255,$A17,Checks!$K$2:$K$255,"UNIQUE",Checks!$J$2:$J$255,"NO INDEPENDENT PRICE") -> 1 | F17: =IF((C17+D17)=0,0,D17/(C17+D17)) -> 0.0625 | G17: =SUMIFS(Checks!$I$2:$I$255,Checks!$B$2:$B$255,$A17,Checks!$K$2:$K$255,"UNIQUE",Checks!$J$2:$J$255,"<>UNMAPPED ASSET CLASS") -> -42680.28 | H17: =SUMIFS(Checks!$I$2:$I$255,Checks!$B$2:$B$255,$A17,Checks!$K$2:$K$255,"UNIQUE",Checks!$J$2:$J$255,"BREACH") -> -21360.208
A18: New York Rates | B18: =COUNTIFS(Checks!$B$2:$B$255,$A18,Checks!$K$2:$K$255,"UNIQUE",Checks!$J$2:$J$255,"OK")+COUNTIFS(Checks!$B$2:$B$255,$A18,Checks!$K$2:$K$255,"UNIQUE",Checks!$J$2:$J$255,"BREACH") -> 32 | C18: =COUNTIFS(Checks!$B$2:$B$255,$A18,Checks!$K$2:$K$255,"UNIQUE",Checks!$J$2:$J$255,"OK") -> 30 | D18: =COUNTIFS(Checks!$B$2:$B$255,$A18,Checks!$K$2:$K$255,"UNIQUE",Checks!$J$2:$J$255,"BREACH") -> 2 | E18: =COUNTIFS(Checks!$B$2:$B$255,$A18,Checks!$K$2:$K$255,"UNIQUE",Checks!$J$2:$J$255,"NO INDEPENDENT PRICE") -> 0 | F18: =IF((C18+D18)=0,0,D18/(C18+D18)) -> 0.0625 | G18: =SUMIFS(Checks!$I$2:$I$255,Checks!$B$2:$B$255,$A18,Checks!$K$2:$K$255,"UNIQUE",Checks!$J$2:$J$255,"<>UNMAPPED ASSET CLASS") -> 2903.496 | H18: =SUMIFS(Checks!$I$2:$I$255,Checks!$B$2:$B$255,$A18,Checks!$K$2:$K$255,"UNIQUE",Checks!$J$2:$J$255,"BREACH") -> -2431.152
A19: Singapore Equities | B19: =COUNTIFS(Checks!$B$2:$B$255,$A19,Checks!$K$2:$K$255,"UNIQUE",Checks!$J$2:$J$255,"OK")+COUNTIFS(Checks!$B$2:$B$255,$A19,Checks!$K$2:$K$255,"UNIQUE",Checks!$J$2:$J$255,"BREACH") -> 38 | C19: =COUNTIFS(Checks!$B$2:$B$255,$A19,Checks!$K$2:$K$255,"UNIQUE",Checks!$J$2:$J$255,"OK") -> 32 | D19: =COUNTIFS(Checks!$B$2:$B$255,$A19,Checks!$K$2:$K$255,"UNIQUE",Checks!$J$2:$J$255,"BREACH") -> 6 | E19: =COUNTIFS(Checks!$B$2:$B$255,$A19,Checks!$K$2:$K$255,"UNIQUE",Checks!$J$2:$J$255,"NO INDEPENDENT PRICE") -> 0 | F19: =IF((C19+D19)=0,0,D19/(C19+D19)) -> 0.15789474 | G19: =SUMIFS(Checks!$I$2:$I$255,Checks!$B$2:$B$255,$A19,Checks!$K$2:$K$255,"UNIQUE",Checks!$J$2:$J$255,"<>UNMAPPED ASSET CLASS") -> 10688.56 | H19: =SUMIFS(Checks!$I$2:$I$255,Checks!$B$2:$B$255,$A19,Checks!$K$2:$K$255,"UNIQUE",Checks!$J$2:$J$255,"BREACH") -> 71685.11
A20: Singapore FX | B20: =COUNTIFS(Checks!$B$2:$B$255,$A20,Checks!$K$2:$K$255,"UNIQUE",Checks!$J$2:$J$255,"OK")+COUNTIFS(Checks!$B$2:$B$255,$A20,Checks!$K$2:$K$255,"UNIQUE",Checks!$J$2:$J$255,"BREACH") -> 24 | C20: =COUNTIFS(Checks!$B$2:$B$255,$A20,Checks!$K$2:$K$255,"UNIQUE",Checks!$J$2:$J$255,"OK") -> 23 | D20: =COUNTIFS(Checks!$B$2:$B$255,$A20,Checks!$K$2:$K$255,"UNIQUE",Checks!$J$2:$J$255,"BREACH") -> 1 | E20: =COUNTIFS(Checks!$B$2:$B$255,$A20,Checks!$K$2:$K$255,"UNIQUE",Checks!$J$2:$J$255,"NO INDEPENDENT PRICE") -> 0 | F20: =IF((C20+D20)=0,0,D20/(C20+D20)) -> 0.041666667 | G20: =SUMIFS(Checks!$I$2:$I$255,Checks!$B$2:$B$255,$A20,Checks!$K$2:$K$255,"UNIQUE",Checks!$J$2:$J$255,"<>UNMAPPED ASSET CLASS") -> -28500.287 | H20: =SUMIFS(Checks!$I$2:$I$255,Checks!$B$2:$B$255,$A20,Checks!$K$2:$K$255,"UNIQUE",Checks!$J$2:$J$255,"BREACH") -> 1232.5029
A21: Zurich Equities | B21: =COUNTIFS(Checks!$B$2:$B$255,$A21,Checks!$K$2:$K$255,"UNIQUE",Checks!$J$2:$J$255,"OK")+COUNTIFS(Checks!$B$2:$B$255,$A21,Checks!$K$2:$K$255,"UNIQUE",Checks!$J$2:$J$255,"BREACH") -> 40 | C21: =COUNTIFS(Checks!$B$2:$B$255,$A21,Checks!$K$2:$K$255,"UNIQUE",Checks!$J$2:$J$255,"OK") -> 35 | D21: =COUNTIFS(Checks!$B$2:$B$255,$A21,Checks!$K$2:$K$255,"UNIQUE",Checks!$J$2:$J$255,"BREACH") -> 5 | E21: =COUNTIFS(Checks!$B$2:$B$255,$A21,Checks!$K$2:$K$255,"UNIQUE",Checks!$J$2:$J$255,"NO INDEPENDENT PRICE") -> 2 | F21: =IF((C21+D21)=0,0,D21/(C21+D21)) -> 0.125 | G21: =SUMIFS(Checks!$I$2:$I$255,Checks!$B$2:$B$255,$A21,Checks!$K$2:$K$255,"UNIQUE",Checks!$J$2:$J$255,"<>UNMAPPED ASSET CLASS") -> -264567.19 | H21: =SUMIFS(Checks!$I$2:$I$255,Checks!$B$2:$B$255,$A21,Checks!$K$2:$K$255,"UNIQUE",Checks!$J$2:$J$255,"BREACH") -> -2140.95
A22: Zurich FX | B22: =COUNTIFS(Checks!$B$2:$B$255,$A22,Checks!$K$2:$K$255,"UNIQUE",Checks!$J$2:$J$255,"OK")+COUNTIFS(Checks!$B$2:$B$255,$A22,Checks!$K$2:$K$255,"UNIQUE",Checks!$J$2:$J$255,"BREACH") -> 16 | C22: =COUNTIFS(Checks!$B$2:$B$255,$A22,Checks!$K$2:$K$255,"UNIQUE",Checks!$J$2:$J$255,"OK") -> 13 | D22: =COUNTIFS(Checks!$B$2:$B$255,$A22,Checks!$K$2:$K$255,"UNIQUE",Checks!$J$2:$J$255,"BREACH") -> 3 | E22: =COUNTIFS(Checks!$B$2:$B$255,$A22,Checks!$K$2:$K$255,"UNIQUE",Checks!$J$2:$J$255,"NO INDEPENDENT PRICE") -> 0 | F22: =IF((C22+D22)=0,0,D22/(C22+D22)) -> 0.1875 | G22: =SUMIFS(Checks!$I$2:$I$255,Checks!$B$2:$B$255,$A22,Checks!$K$2:$K$255,"UNIQUE",Checks!$J$2:$J$255,"<>UNMAPPED ASSET CLASS") -> 78262.765 | H22: =SUMIFS(Checks!$I$2:$I$255,Checks!$B$2:$B$255,$A22,Checks!$K$2:$K$255,"UNIQUE",Checks!$J$2:$J$255,"BREACH") -> 33806.69
A23: Total | B23: =SUM(B15:B22) -> 242 | C23: =SUM(C15:C22) -> 220 | D23: =SUM(D15:D22) -> 22 | E23: =SUM(E15:E22) -> 6 | F23: =IF((C23+D23)=0,0,D23/(C23+D23)) -> 0.090909091 | G23: =SUM(G15:G22) -> -233682.36 | H23: =SUM(H15:H22) -> 108012.63
A26: Data Quality
A27: Check | B27: Count
A28: Raw rows loaded | B28: =COUNTA(Raw_Data!A2:A255) -> 254
A29: Duplicate rows removed | B29: =COUNTIF(Checks!$K$2:$K$255,"DUP") -> 4
A30: Unique positions | B30: =COUNTIF(Checks!$K$2:$K$255,"UNIQUE") -> 250
A31: Missing independent price | B31: =COUNTIFS(Checks!$J$2:$J$255,"NO INDEPENDENT PRICE",Checks!$K$2:$K$255,"UNIQUE") -> 6
A32: Unmapped asset class | B32: =COUNTIFS(Checks!$J$2:$J$255,"UNMAPPED ASSET CLASS",Checks!$K$2:$K$255,"UNIQUE") -> 2
A33: Stale valuation date | B33: =COUNTIFS(Checks!$L$2:$L$255,"STALE",Checks!$K$2:$K$255,"UNIQUE") -> 5
